Workbook

Sheet How to use
B5: Purpose
B7: This E-E-A-T audit checklist helps SEO professionals systematically assess their website's Experience, Expertise, Authority, and Trust signals against Google's Search Quality Evaluator Guidelines, with each item cross-referenced to specific guideline sections. The automated dashboard calculates scores to identify gaps and prioritize improvements.
B9: How to use this checklist
B11: STEP 1: | C11: Review the Scoring Guide
C12: Familiarize yourself with Google's Quality Scale as described in the Quality Rater Guidelines (QRG)
C13: Understand what each score level means
B15: STEP 2: | C15: Complete the Audit
C16: Go to the Brand + Website, People, and Pages tabs
C17: For each checklist item, assess your site and select a score from the dropdown
C18: Scores: 1 (Lowest), 25 (Low), 50 (Medium), 75 (High), 100 (Highest)
B20: STEP 3: | C20: Use the Dashboard
C21: The Dashboard automatically calculates your E-E-A-T scores
C22: View scores by: Entity Type, E-E-A-T Component, Overall
C23: Identify your weakest areas to prioritize improvements
B25: STEP 4: | C25: Build Your Action Plan
C26: Use the lowest-scoring items to create a prioritized improvement list
C27: Focus on Trust signals first (most important per Google)
C28: For YMYL sites, prioritize Expertise and Authority
C29: Use the 'Next Step' column to plan implementation
B31: STEP 5: | C31: Present to Stakeholders
C32: Use Dashboard scores to show the current state
C33: Identify gaps with specific examples from the checklist
C34: Estimate effort/cost to close gaps
C35: Plan actions approved by stakeholders as tasks in your project management platform
B38: IMPORTANT NOTES:
C39: • E-E-A-T is assessed based on 1) what the website says about itself, 2) what independent reliable sources say about it, and 3) what's visible on the page itself
C40: • E-E-A-T applies to the website as a whole, the owners of the website (as individuals or organizations), the creators of the content of each page and the content itself
C41: • Trust is the most important E-E-A-T component. Prioritize it
C42: • Reputation is an unofficial element of E-E-A-T that connects to trust but is what quality raters look for most
C43: • Reputation research should look for independent, credible sources
C44: • YMYL topics (health, finance, safety, legal) have higher standards
C45: • Both Experience and Expertise are valuable - depends on topic/purpose, even for YMYL topics
C46: • This checklist is based on Google Search Quality Evaluator Guidelines (Sept 11, 2025)

Sheet Dashboard
A1: E-E-A-T AUDIT DASHBOARD
A3: INSTRUCTIONS:
A4: 1. Complete audit in the Brand + Website, People, and Pages tabs
A5: 2. Use Google's Quality Scale: Lowest (0), Low (25), Medium (50), High (75), Highest (100)
A6: 3. Scores auto-calculate below based on your ratings
A7: 4. Use findings to identify gaps and secure stakeholder buy-in
A9: OVERALL E-E-A-T SCORES
A11: Entity Type | B11: Experience | C11: Expertise | D11: Authoritativeness | E11: Trust | F11: Overall E-E-A-T
A12: Brand + Website | B12: =iferror(AVERAGEIF('Brand + Website'!$C:$C,"*Experience*",'Brand + Website'!$F:$F),"") | C12: =iferror(AVERAGEIF('Brand + Website'!$C:$C,"*Expertise*",'Brand + Website'!$F:$F),"") | D12: =iferror(AVERAGEIF('Brand + Website'!$C:$C,"*Authorit*",'Brand + Website'!$F:$F),"") | E12: =iferror(AVERAGEIF('Brand + Website'!$C:$C,"*Trust*",'Brand + Website'!$F:$F),"") | F12: =iferror(AVERAGE(B12:E12),"")
A13: People | B13: =iferror(AVERAGEIF(People!$C:$C,"*Experience*",People!$F:$F),"") | C13: =iferror(AVERAGEIF(People!$C:$C,"*Expertise*",People!$F:$F),"") | D13: =iferror(AVERAGEIF(People!$C:$C,"*Authorit*",People!$F:$F),"") | E13: =iferror(AVERAGEIF(People!$C:$C,"*Trust*",People!$F:$F),"") | F13: =iferror(AVERAGE(B13:E13),"")
A14: Pages | B14: =iferror(AVERAGEIF(Pages!$C:$C,"*Experience*",Pages!$F:$F),"") | C14: =iferror(AVERAGEIF(Pages!$C:$C,"*Expertise*",Pages!$F:$F),"") | D14: =iferror(AVERAGEIF(Pages!$C:$C,"*Authorit*",Pages!$F:$F),"") | E14: =iferror(AVERAGEIF(Pages!$C:$C,"*Trust*",Pages!$F:$F),"") | F14: =iferror(AVERAGE(B14:E14),"")
A16: TOTAL | B16: =iferror(AVERAGE(B12:B14),"") | C16: =iferror(AVERAGE(C12:C14),"") | D16: =iferror(AVERAGE(D12:D14),"") | E16: =iferror(AVERAGE(E12:E14),"") | F16: =iferror(AVERAGE(F12:F14),"")
A19: E-E-A-T COMPONENT BREAKDOWN
A21: Component | B21: Description | C21: Average Score | D21: Priority Focus
A22: Experience | B22: First-hand, life experience with the topic | C22: =B16 | D22: =IF(C22="","Not Scored",IF(C22<=40,"Critical",IF(C22<=60,"High",IF(C22<=75,"Medium","Low")))) -> Not Scored
A23: Expertise | B23: Skill, knowledge, and educational credentials | C23: =C16 | D23: =IF(C23="","Not Scored",IF(C23<=40,"Critical",IF(C23<=60,"High",IF(C23<=75,"Medium","Low")))) -> Not Scored
A24: Authority | B24: Go-to source, industry recognition | C24: =D16 | D24: =IF(C24="","Not Scored",IF(C24<=40,"Critical",IF(C24<=60,"High",IF(C24<=75,"Medium","Low")))) -> Not Scored
A25: Trust | B25: Most important - accuracy, honesty, safety | C25: =E16 | D25: =IF(C25="","Not Scored",IF(C25<=40,"Critical",IF(C25<=60,"High",IF(C25<=75,"Medium","Low")))) -> Not Scored

Sheet Brand + Website
B1: Brand + Website E-E-A-T Signals
A4: Checklist Item | B4: Source | C4: Category | D4: Entity to Check | E4: Score | F4: Score % | G4: Notes | H4: Next Step
A5: Foundational Branding | B5: These are founadtional elements that establish your brand is a real entity and worth including in search results | F5: {=ifna(vlookup(E5:E152,'Scoring Guide'!A6:B10,2,false),"")}
A6: Brand is well-known and respected in the industry | B6: QRG sections 3.3.1 & 8.3 | C6: Authority, Trust, Reputation | D6: Website Owner / Organization
A7: Brand has established a solid, consistent foundation online, making it clear who is responsible for the website | B7: QRG sections 2.5.2 & 3.3.1 | C7: Trust, Foundational | D7: Brand (Off-Site)
A8: Website has a clear topic focus or is aligned with a distinct product category | B8: QRG sections 7.3 & 8.3 | C8: Authority, Foundational | D8: Website
A9: Website's URL matches the intended purpose and content that's present on the website | B9: QRG section 4.6.3 | C9: Trust | D9: Website
A10: Website features full Organization schema (especially on the homepage) | B10: Not in QRG but is a structured data set search systems can use | C10: Foundational | D10: Website
A12: Contact Details | B12: These are common contact details Google search evaluators look for to establish an organization's authenticity and trustworthiness
A13: Phone number (ideally a local one) is clearly visible on the website | B13: QRG sections 2.5.3 & 4.5.1 | C13: Trust, Foundational | D13: Website
A14: Physical address (not a virtual or mailbox address) is clearly visible on the website | B14: QRG sections 2.5.3 & 4.5.1 | C14: Trust, Foundational | D14: Website
A15: Contact details that connect to human support staff are signposted and easy to find on the website | B15: QRG sections 2.5.3 & 4.5.1 | C15: Trust, Foundational | D15: Website
A16: Every core page features clear contact information or an obvious link to it | B16: QRG sections 2.5.3 & 4.5.1 | C16: Trust, Foundational | D16: Page
A18: Brand Entity | B18: These indicate whether your brand is established as it's own entity in search systems (crucial for AI visibility too)
A19: Brand has a detailed and up-to-date Wikipedia page (essential for large companies, optional for smaller ones) | B19: QRG sections 3.3.1 & 3.3.3 | C19: Authority, Trust, Reputation | D19: Brand (Off-Site)
A20: Brand has a knowledge panel on Google, and it is claimed | B20: Indicates Google recognizes your brand as an entity based on its online reputation | C20: Trust, Authority | D20: Search Results
A21: Brand has a knowledge panel on Bing, and it is claimed | B21: Not part of Google guidelines, but establishes your brand on more search platforms | C21: Trust, Authority | D21: Search Results
A23: Business Listings | B23: These establish your brand's official off-site local properties and ensure accurate information to enhance trust signals
A24: Brand has an active Google Business Listing that it's claimed and is the owner of | B24: QRG section 2.5 | C24: Authority, Trust | D24: Brand (Off-Site)
A25: Brand's Google Business Listing is accurate and optimized well for local visibility | B25: QRG section 2.5 | C25: Authority, Trust | D25: Brand (Off-Site)
A26: Brand has Bing Places and Apple Maps listings, and info is up-to-date and accurate | B26: Not part of Google guidelines, but establishes your brand on more search platforms | C26: Authority, Foundational | D26: Brand (Off-Site)
A27: Brand has citations from authoritative business listings and local directory sites like Yelp | B27: QRG section 3.3 | C27: Authority, Reputation, Trust | D27: Brand (Off-Site)
A28: Brand's local citations and listings have accurate name, address, phone, and website details | B28: QRG section 2.5 | C28: Trust, Foundational | D28: Brand (Off-Site)
A30: Brand Profiles | B30: These establish your brand's official off-site properties that enhance its reputation. They can be seen as authoritative sources of information about the brand
A31: Brand has claimed official social profiles on major platforms (even if inactive, protect from others claiming them and own all authoritative sources of information about the brand) | B31: QRG section 2.5 & 3.3 | C31: Authority, Foundational | D31: Brand (Off-Site)
A32: Brand has filled out core information on each social media profile to establish its foundational presence | B32: QRG section 2.5 & 3.3 | C32: Trust, Foundational | D32: Brand (Off-Site)
A33: Brand links to its website from all official social media profiles | B33: QRG section 2.5 & 3.3 | C33: Authority, Foundational | D33: Brand (Off-Site)
A34: Website features links to official branded social media profiles | B34: QRG section 2.5 & 3.3 | C34: Trust | D34: Website
A35: Brand maintains (at least) some active social profiles and publishes content about relevant topics | B35: QRG sections 7.2 & 8.2 | C35: Authority, Expertise | D35: Brand (Off-Site)
A36: Brand participates in online forums and discussions, sharing its expertise where appropriate | B36: QRG section 3.3.4 | C36: Authority, Expertise | D36: Brand (Off-Site)
A37: Brand's Wikipedia page opens with "{Brand} is an {country} {product category} company headquartered in {location}..." | B37: QRG sections 3.3 & 3.4 | C37: Authority, Reputation, Trust | D37: Brand (Off-Site)
A38: Brand's Wikipedia page contains up-to-date business name and HQ address | B38: QRG sections 3.3 & 3.4 | C38: Authority, Reputation, Trust | D38: Brand (Off-Site)
A39: Brand's Wikipedia page contains a section about the company's history | B39: QRG sections 3.3 & 3.4 | C39: Authority, Reputation, Trust | D39: Brand (Off-Site)
A40: Brand's Wikipedia page contains links and mentions to key products and sub-brands | B40: QRG sections 3.3 & 3.4 | C40: Authority, Reputation, Trust | D40: Product / Service
A41: Brand's Wikipedia page contains foundational information like who, when, where and why it was founded | B41: QRG sections 3.3 & 3.4 | C41: Authority, Reputation, Trust | D41: Brand (Off-Site)
A42: Brand's Wikipedia page contains information about the company's corporate structure | B42: QRG sections 3.3 & 3.4 | C42: Authority, Reputation, Trust | D42: Website Owner / Organization
... A45: Brand's Wikipedia page includes key people like founders, chairpeople, investors and executives | B45: QRG sections 3.3 & 3.4 | C45: Authority, Reputation, Trust | D45: Person
A47: Reviews + Testimonials | B47: These are a measure of your brand's reputation both on and off the website based on reviews and testimonials of people who have experience working with you/buying from you
A48: Brand has many positive Google reviews | B48: QRG sections 3.3 & 3.4 | C48: Authority, Reputation, Trust | D48: Brand (Off-Site)
A49: Brand has many positive reviews on social media, like Facebook | B49: QRG sections 3.3 & 3.4 | C49: Authority, Reputation, Trust | D49: Brand (Off-Site)
...

Sheet People
B1: E-E-A-T Signals Connected to People
A4: Checklist Item | B4: Source | C4: Category | D4: Entity to Check | E4: Score | F4: Score % | G4: Notes | H4: Next Step
A5: Foundational Personal Branding (All People) | B5: These are founadtional elements that establish you as a real entity with topical expertise and/or authority earned from companies you've worked at | F5: {=ifna(vlookup(E5:E68,'Scoring Guide'!A6:B10,2,false),"")}
A6: Person has a strong reputation in the industry or is seen as an influencer | B6: QRG sections 3.3 & 8.2 | C6: Authority, Reputation, Trust | D6: Person
A7: Person is seen as trustworthy by their audience | B7: QRG section 3.3 | C7: Trust, Reputation | D7: Person
A8: Person is transparent about their background and experience | B8: QRG section 3.3 | C8: Experience, Trust | D8: Person
A9: Person has received awards or honors for their work | B9: QRG section 8.1 | C9: Expertise, Authority | D9: Person
A10: Person has a standalone profile page on the website | B10: QRG section 3.3 | C10: Trust, Foundational | D10: Person
A11: Person has a Wikipedia page about them | B11: QRG section 3.3 | C11: Authority, Reputation, Trust | D11: Person
A12: Person has been featured on relevant podcasts, webinars, and interviews and they link to the homepage or their bio page | B12: QRG section 3.3 | C12: Authority, Reputation, Trust | D12: Person
A13: Person has guest-posted or been featured in authoritative content on other publications | B13: QRG section 3.3 | C13: Authority, Reputation, Trust | D13: Person
A14: Person regularly gets cited in the press as an expert on their main topic of expertise | B14: QRG section 3.3 | C14: Expertise, Authority | D14: Person
A15: Person has professional social profiles they actively use | B15: QRG section 3.3 | C15: Trust, Reputation | D15: Person
A16: Person has an active audience on social media | B16: QRG section 3.3 | C16: Authority, Trust | D16: Person
A17: Person frequently posts about their topic of expertise and gets decent engagement | B17: QRG section 3.3 | C17: Expertise, Authority | D17: Person
... A20: Person has citations / a bio on relevant professional sites like MuckRack, IMDB etc | B20: QRG section 3.3 | C20: Trust, Reputation | D20: Person
A22: Off-Site Profiles (All People) | B22: These establish your official profiles and enhance your reputation. They can be seen as authoritative sources of information about you and used as data sources by search systems
A23: Person's Wikipedia page contains their full name and current company they work for | B23: QRG section 3.3 | C23: Foundational, Reputation, Trust | D23: Person
A24: Person's Wikipedia page opens with "{Name} is an {ethnicity} {job title, or list of relevant titles}, known for {x,y and z}." | B24: QRG section 3.3 | C24: Authority, Reputation, Trust | D24: Person | G24: e.g. Arnie: Arnold Alois Schwarzenegger[b] (born July 30, 1947) is an Austrian and American actor, businessman, former politician, and former professional bodybuilder, known for his roles in high-profile action films. He served as the 38th governor of California from 2003 to 2011.[3] https://en.wikipedia.org/wiki/Arnold_Schwarzenegger
A25: Person's Wikipedia page contains a summary section of their career highlights after intro | B25: QRG section 3.3 | C25: Experience | D25: Person
A26: Person's Wikipedia page contains a professional headshot or image | B26: QRG section 3.3 | C26: Trust | D26: Person
A27: Person's Wikipedia page contains a section on awards, accolades or commendations they've won | B27: QRG section 3.3 | C27: Expertise, Authority | D27: Person
A28: Person's Wikipedia page contains a section on PhDs, original research or patents they've contributed to | B28: QRG section 3.3 | C28: Expertise | D28: Person
A29: Person's Wikipedia page contains a section on their education and qualifications | B29: QRG section 3.3 | C29: Expertise | D29: Person
A30: Person's Wikipedia page contains summary of what skills and topics they're known for professionally | B30: QRG section 3.3 | C30: Expertise, Reputation | D30: Person
A31: Person's Wikipedia page contains a section on their relevant work history at publically traded companies or big organizations they've worked for | B31: QRG section 3.3 | C31: Experience, Trust, Authority | D31: Person
A32: Person's Wikipedia page contains reference links to their profile page on company website | B32: QRG section 3.3 | C32: Authority, Trust | D32: Person
A33: Person's Wikipedia page contains off-site links to press and media articles mentioning them positively | B33: QRG section 3.3 | C33: Authority, Trust, Reputation | D33: Person
A35: Presence in Search Engines (All People) | B35: These are performance indicators that could be used as E-E-A-T signals by search systems
A36: Person's name gets direct searches on Google | B36: A measure of authority and trust from your audience | C36: Authority, Reputation, Trust | D36: Search Results
A37: Person has a knowledge panel on Google and/or is understood as an entity by Google | B37: Indicates Google recognizes you as an entity based on your online reputation | C37: Trust, Authority | D37: Search Results
A38: Person has a knowledge panel on Bing and/or is understood as an entity by Bing | B38: Not part of Google guidelines, but establishes your presence on more search platforms | C38: Trust, Authority | D38: Search Results
A39: Person's knowledge panels in search engines connect them to the brand and/or link to the website | B39: A measure of accuracy and also authority if you've worked at large companies | C39: Trust, Authority | D39: Search Results
A40: Person's knowledge panels in search engines connect them to their main topic of expertise | B40: A measure of your expertise and authority for a topic, from your audience | C40: Expertise, Reputation | D40: Search Results
A41: Person's name is mentioned in AI responses about the topic or your brand | B41: A measure of authority and expertise, from Google's AI systems | C41: Authority, Trust | D41: Search Results
A42: Person's search results on Google feature their social profiles, bio pages and articles they're mentioned on | B42: A measure of accuracy and authority, from Google search | C42: Authority, Reputation, Trust | D42: Search Results
A43: Person's content is frequently cited in AI responses about their topic of expertise and/or your brand | B43: A measure of quality and trust for your content, from Google's AI systems | C43: Expertise, Authority | D43: Search Results
A45: Authors | B45: Google's quality raters perform E-E-A-T and reputation checks for individual content creators as well as the website and page they're evaluating
A46: Author is recognized as an expert in the field they're writing about | B46: QRG section 3.3.4 | C46: Expertise, Authority | D46: Person
A47: Author demonstrates their knowledge of the latest research and cites it in their content | B47: QRG section 3.3.4 | C47: Expertise | D47: Person
...

Sheet Pages
B1: E-E-A-T Signals on the Page Itself
A4: Checklist Item | B4: Source | C4: Category | D4: Entity to Check | E4: Score | F4: Score % | G4: Notes | H4: Next Step
A5: Authorship (All Pages) | B5: E-E-A-T checks start from individual pages which must clearly indicate who created the main content visible on the page | F5: {=ifna(vlookup(E5:E75,'Scoring Guide'!A6:B10,2,false),"")}
A6: Page contains expert author + reviewer bylines | B6: QRG sections 2.5.2 & 3.3.4 | C6: Trust, Expertise | D6: Page
A7: Page links to standalone author + reviewer profile pages | B7: QRG sections 2.5.2 & 3.3.4 | C7: Trust | D7: Page
A8: Page contains Author and/or reviewedBy schema markup | B8: Not in QRG but is a structured data set search systems can use | C8: Foundational | D8: Page
A10: Topical Depth + Expertise (All Pages) | B10: Google's measure of E-E-A-T is usually with respect to the page's main topic.
A11: Page's intended purpose is clear and fulfilled by the content and/or design | B11: QRG section 2.2 | C11: Trust | D11: Page
A12: Content aligns with the key topical focus of the website and brand | B12: QRG section 1.0 | C12: Trust, Authority | D12: Page
A13: Content avoids sensationalism, clickbait titles and misleading information | B13: QRG section 4.0 | C13: Trust | D13: Page
A14: Content features original multimedia like photos, custom images, videos and/or audio that show first-hand experience | B14: QRG sections 4.6.6 & 5.2 | C14: Experience, Trust | D14: Page
A15: Content includes original thinking and adds value instead of summarizing other people's content | B15: QRG section 4.0 | C15: Expertise, Authority | D15: Page
A16: Content includes evidence and links to authoritative sources to validate claims | B16: QRG section 4.4 | C16: Authority, Trust | D16: Page
A17: Content that's most valuable and helpful is placed prominently or as close to the top as possible | B17: QRG section 5.2.2 | C17: Authority, Expertise | D17: Page
A18: Content contains substantive details or information an expert would usually include | B18: QRG section 5.2.2 | C18: Expertise | D18: Page
A19: Page looks and feels trustworthy | B19: QRG section 3.4 | C19: Trust, Reputation | D19: Page
A21: Production Process + AI Usage (All Pages) | B21: Google looks for effort, originality, talent/skill and accuracy as measures of content quality. Scaled content abuse and low-effort AI content are used as examples of "Lowest" E-E-A-T as a result
A22: Author explains how content was created + methodology behind original data or research | B22: QRG section 3.2 | C22: Experience, Trust | D22: Page
A23: Author indicates how much human effort was invested to create the content | B23: QRG section 4.6.5 | C23: Experience, Trust | D23: Page
A24: Content feels like it's written by an expert / trustworthy source or in the case of experience shared, from a real human, not AI | B24: QRG section 3.2 | C24: Expertise, Experience, Trust | D24: Page
A25: Content is free from obvious AI-isms, slop or SEO filler content | B25: QRG section 5.2 | C25: Trust | D25: Page
A27: Content + Search Performance (All Content) | B27: These are page-level performance indicators that could be used as E-E-A-T signals by search systems
A28: Page has many authoritative backlinks | B28: QRG section 3.3.1 | C28: Authority, Reputation, Trust | D28: Page
A29: Content has many authoritative mentions around the web | B29: QRG section 3.3.1 | C29: Authority, Reputation, Trust | D29: Page
A30: Content matches search intent for the target keyword | C30: Foundational, Trust | D30: Page
A31: Content ranks well for unbranded, relevant keywords about the topic | C31: Authority | D31: Page
A32: Page is cited in relevant AI answers about the topic | C32: Authority, Reputation, Trust | D32: Page
A34: YMYL Content | B34: "Your Money or Your Life" content is held to a stricter standard for E-E-A-T requirements
A35: Content is safe to trust for topics about your money or your life, and shares appropriate expertise to prevent harm | B35: QRG section 4.4 | C35: Trust, Expertise | D35: Page
A36: Content about YMYL topics conforms to the consensus backed by research | B36: QRG sections 4.4 & 11 | C36: Trust | D36: Page
A37: All YMYL content features an expert reviewer and makes their credentials clear to readers even when skimming | B37: QRG sections 3.4. & 11 | C37: Expertise, Trust | D37: Page
A38: Content includes trustworthy and safe first-hand accounts and life experience for instances when searchers are seeking comfort or inspiration rather than factual info about a YMYL topic | B38: QRG section 3.4.1 | C38: Experience, Trust | D38: Page
A40: Home | B40: The homepage is a very common page that quality raters and visitors will look to assess your website's E-E-A-T and trustworthiness
A41: Homepage contains logos of awards, certifications and accreditations earned by the company | B41: QRG section 2.5.1 | C41: Authority, Reputation, Trust | D41: Page
A42: Homepage contains logos of big brands that are clients, have mentioned the company and/or are in partnership with the company | B42: QRG section 2.5.1 | C42: Authority, Reputation, Trust | D42: Page
A43: Homepage contains testimonials and reviews from happy customers | B43: QRG section 2.5.1 | C43: Experience, Trust, Reputation | D43: Page
A44: Homepage contains detailed Organizational schema | B44: Not in QRG but is a structured data set search systems can use | C44: Authority, Foundational | D44: Page
A45: Homepage connects the brand to its main topics and product categories | B45: QRG section 2.5.1 | C45: Foundational, Reputation, Trust | D45: Page
A47: About | B47: The about page is used to determine who is responsible for a wesbite. It is also used during reputation research to assess potential deception in how the website represents itself
A48: About page is linked in the main navigation and/or the footer so visitors can easily find it | B48: QRG section 2.5.3, 3.4 & 4.5 | C48: Trust | D48: Page
...

Sheet Scoring Guide
A1: E-E-A-T AUDIT SCORING GUIDE
A3: Google's Quality Scale
A5: Google's Scoring | B5: % Score (For Dashboard) | C5: When to Use
A6: Lowest | B6: 1 | C6: Signal is completely absent or demonstrates clear deception/harm/untrustworthiness.
A7: Low | B7: 25 | C7: Weak presence, inconsistent, or inadequate for purpose.
A8: Medium | B8: 50 | C8: Meets basic expectations but not particularly strong. Nothing wrong, but nothing special.
A9: High | B9: 75 | C9: Well-established across relevant places, demonstrates quality and trustworthiness.
A10: Highest | B10: 100 | C10: Multiple strong sources, leaves no doubt, exceeds expectations, among the very best for the topic.
A12: E-E-A-T Components Explained
A14: Component | B14: Definition (Google) | C14: Examples
A15: Experience | B15: First-hand or life experience with the topic | C15: Product reviewer who owns the product; cancer patient sharing treatment experience
A16: Expertise | B16: Skill, knowledge, or educational/professional credentials | C16: Doctor writing about medicine; certified accountant on tax topics
A17: Authoritativeness | B17: Recognition as a go-to source in the field | C17: Mayo Clinic for health; IRS for tax information; IEEE for technical standards
A18: Trust | B18: Accuracy, honesty, safety, and reliability (MOST IMPORTANT) | C18: Secure transactions; accurate information; clear author attribution; no deceptive practices

Sheet Sources
A1: Official References and Sources Used
A3: All Google Documentation Referenced
A5: Resource Type | B5: Title/Description | C5: URL | D5: E-E-A-T Focus
A6: Primary Guidelines | B6: Search Quality Evaluator Guidelines (September 2025) | C6: https://static.googleusercontent.com/media/guidelines.raterhub.com/en//searchqualityevaluatorguidelines.pdf | D6: Core E-E-A-T framework, YMYL, Page Quality, Reputation
A7: Primary Guidelines | B7: Search Quality Rater Guidelines: An Overview | C7: https://services.google.com/fh/files/misc/hsw-sqrg.pdf | D7: Same as above (alternative source)
A8: Official Blog | B8: Google Rater Guidelines: E-E-A-T (December 2022) | C8: https://developers.google.com/search/blog/2022/12/google-raters-guidelines-e-e-a-t | D8: Official announcement of adding "Experience" to E-A-T
A9: Official Blog | B9: Search Quality Rater Guidelines Update (November 2023) | C9: https://developers.google.com/search/blog/2023/11/search-quality-rater-guidelines-update | D9: Latest updates to Quality Rater Guidelines
A10: Official Blog | B10: Core Updates & E-A-T (August 2019) | C10: https://developers.google.com/search/blog/2019/08/core-updates#get-to-know-the-quality-rater-guidelines-and-e-a-t | D10: Introduction to E-A-T concept, relationship to core updates
A11: Developer Docs | B11: Creating Helpful Content | C11: https://developers.google.com/search/docs/fundamentals/creating-helpful-content | D11: Page quality, people-first content (relates to E-E-A-T)
A12: Official Blog | B12: Helpful Content Update (August 2022) | C12: https://developers.google.com/search/blog/2022/08/helpful-content-update | D12: Quality signals, people-first content approach
A13: Official Blog | B13: How Google Delivers Reliable Information in Search | C13: https://blog.google/products-and-platforms/products/search/how-google-delivers-reliable-information-search/ | D13: Trust and reliability (core E-E-A-T component)
A14: Official Blog | B14: How Raters & Experiments Improve Google Search | C14: https://blog.google/products-and-platforms/products/search/raters-experiments-improve-google-search/ | D14: Role of quality raters in evaluating E-E-A-T
A15: Developer Docs | B15: Google Search & AI-Generated Content (February 2023) | C15: https://developers.google.com/search/blog/2023/02/google-search-and-ai-content | D15: Quality expectations regardless of content source
A17: Google Search Quality Evaluator Guidelines Reference
A19: See full guidelines at https://static.googleusercontent.com/media/guidelines.raterhub.com/en//searchqualityevaluatorguidelines.pdf
A20: Version: September 11, 2025
A22: Section | B22: Title | C22: Key Focus for E-E-A-T
A23: 2.2 | B23: Understanding the Purpose of a Webpage | C23: Assess if page purpose is clear and beneficial. Foundational for determining appropriate E-E-A-T standards
A24: 2.3 | B24: Your Money or Your Life (YMYL) Topics | C24: Identify if content requires higher E-E-A-T standards due to potential impact on health, finance, safety, or welfare
A25: 2.4.1 | B25: Identifying the Main Content (MC) | C25: Evaluate the quality and substance of primary content. Core area for demonstrating expertise and experience
A26: 2.4.2 | B26: Identifying the Supplementary Content (SC) | C26: Assess if supporting content enhances user experience without distracting from main content quality
A27: 2.4.3 | B27: Identifying Advertisements/Monetization | C27: Ensure ads don't interfere with content or undermine trust through excessive/deceptive monetization
A28: 2.5 | B28: Finding Who is Responsible for Website/Content Creator | C28: Verify clear attribution and credentials - critical for establishing expertise, authoritativeness, and trust
A29: 3.0 | B29: Overall Page Quality Rating | C29: Understand the holistic framework for assessing page quality based on purpose, content, and E-E-A-T
A30: 3.2 | B30: Quality of the Main Content | C30: Evaluate content accuracy, depth, originality - demonstrates expertise and experience in topic
A31: 3.3 | B31: Reputation of Website and Content Creators | C31: Research independent sources to verify credibility - reputation is key indicator of authoritativeness
A32: 3.3.1 | B32: Reputation of the Website | C32: Find external evidence of website's standing in industry through awards, press, expert opinions
A33: 3.3.2 | B33: Customer Reviews as Reputation Information | C33: Assess credible customer reviews as trust and reputation signals, particularly for commerce sites
A34: 3.3.3 | B34: How to Search for Reputation Information | C34: Learn methodology for finding independent, reliable sources about website/creator reputation
A35: 3.3.4 | B35: Reputation of the Content Creators | C35: Verify individual authors' credentials, recognition, and independent mentions as experts
A36: 3.4 | B36: Experience, Expertise, Authoritativeness, Trust (E-E-A-T) | C36: Core framework - understand how these four components work together, with Trust as most important
A37: 3.4.1 | B37: YMYL Topics: Experience or Expertise? | C37: Determine when first-hand experience vs. formal expertise is more appropriate for topic/purpose
A38: 4.0 | B38: Lowest Quality Pages | C38: Identify red flags that result in lowest ratings - harm, deception, lack of purpose, untrustworthiness
A39: 4.5 | B39: Untrustworthy Webpages or Websites | C39: Recognize signs of untrustworthiness that override all other positive E-E-A-T signals
A40: 4.5.1 | B40: Inadequate Information about Website/Content Creator | C40: Flag insufficient transparency about who's responsible - major trust issue, especially for YMYL
... A48: 8.3 | B48: Very High Level of E-E-A-T | C48: Understand what exceptional E-E-A-T looks like - multiple strong signals across all components
